[2024-03-26 06:16:54,086: WARNING/MainProcess] /usr/local/lib/python3.10/site-packages/celery/worker/consumer/consumer.py:507: CPendingDeprecationWarning: The broker_connection_retry configuration setting will no longer determine
whether broker connection retries are made during startup in Celery 6.0 and above.
If you wish to retain the existing behavior for retrying connections on startup,
you should set broker_connection_retry_on_startup to True.
  warnings.warn(

[2024-03-26 06:16:54,147: INFO/MainProcess] Connected to redis://redis:6379/0
[2024-03-26 06:16:54,149: WARNING/MainProcess] /usr/local/lib/python3.10/site-packages/celery/worker/consumer/consumer.py:507: CPendingDeprecationWarning: The broker_connection_retry configuration setting will no longer determine
whether broker connection retries are made during startup in Celery 6.0 and above.
If you wish to retain the existing behavior for retrying connections on startup,
you should set broker_connection_retry_on_startup to True.
  warnings.warn(

[2024-03-26 06:16:54,160: INFO/MainProcess] mingle: searching for neighbors
[2024-03-26 06:16:55,178: INFO/MainProcess] mingle: all alone
[2024-03-26 06:16:55,198: INFO/MainProcess] celery@df598207fd15 ready.
[2024-03-26 06:16:58,380: INFO/MainProcess] Events of group {task} enabled by remote.
[2024-03-26 06:17:00,060: INFO/MainProcess] Task tracker.tasks.cel_scraper[5eed758b-d050-48a7-93cf-a83506c2919a] received
[2024-03-26 06:17:00,108: ERROR/MainProcess] Task tracker.tasks.cel_scraper[5eed758b-d050-48a7-93cf-a83506c2919a] raised unexpected: OperationalError('connection to server at "localhost" (127.0.0.1), port 5432 failed: Connection refused\n\tIs the server running on that host and accepting TCP/IP connections?\nconnection to server at "localhost" (::1), port 5432 failed: Cannot assign requested address\n\tIs the server running on that host and accepting TCP/IP connections?\n')
Traceback (most recent call last):
  File "/usr/local/lib/python3.10/site-packages/django/db/backends/base/base.py", line 275, in ensure_connection
    self.connect()
  File "/usr/local/lib/python3.10/site-packages/django/utils/asyncio.py", line 26, in inner
    return func(*args, **kwargs)
  File "/usr/local/lib/python3.10/site-packages/django/db/backends/base/base.py", line 256, in connect
    self.connection = self.get_new_connection(conn_params)
  File "/usr/local/lib/python3.10/site-packages/django/utils/asyncio.py", line 26, in inner
    return func(*args, **kwargs)
  File "/usr/local/lib/python3.10/site-packages/django/db/backends/postgresql/base.py", line 277, in get_new_connection
    connection = self.Database.connect(**conn_params)
  File "/usr/local/lib/python3.10/site-packages/psycopg2/__init__.py", line 122, in connect
    conn = _connect(dsn, connection_factory=connection_factory, **kwasync)
psycopg2.OperationalError: connection to server at "localhost" (127.0.0.1), port 5432 failed: Connection refused
	Is the server running on that host and accepting TCP/IP connections?
connection to server at "localhost" (::1), port 5432 failed: Cannot assign requested address
	Is the server running on that host and accepting TCP/IP connections?


The above exception was the direct cause of the following exception:

Traceback (most recent call last):
  File "/usr/local/lib/python3.10/site-packages/celery/app/trace.py", line 477, in trace_task
    R = retval = fun(*args, **kwargs)
  File "/usr/local/lib/python3.10/site-packages/celery/app/trace.py", line 760, in __protected_call__
    return self.run(*args, **kwargs)
  File "/usr/src/app/tracker/tasks.py", line 14, in cel_scraper
    scraper.scrape()
  File "/usr/src/app/tracker/Utils/Scraper.py", line 21, in scrape
    for  product in urls:
  File "/usr/local/lib/python3.10/site-packages/django/db/models/query.py", line 400, in __iter__
    self._fetch_all()
  File "/usr/local/lib/python3.10/site-packages/django/db/models/query.py", line 1928, in _fetch_all
    self._result_cache = list(self._iterable_class(self))
  File "/usr/local/lib/python3.10/site-packages/django/db/models/query.py", line 91, in __iter__
    results = compiler.execute_sql(
  File "/usr/local/lib/python3.10/site-packages/django/db/models/sql/compiler.py", line 1560, in execute_sql
    cursor = self.connection.cursor()
  File "/usr/local/lib/python3.10/site-packages/django/utils/asyncio.py", line 26, in inner
    return func(*args, **kwargs)
  File "/usr/local/lib/python3.10/site-packages/django/db/backends/base/base.py", line 316, in cursor
    return self._cursor()
  File "/usr/local/lib/python3.10/site-packages/django/db/backends/base/base.py", line 292, in _cursor
    self.ensure_connection()
  File "/usr/local/lib/python3.10/site-packages/django/utils/asyncio.py", line 26, in inner
    return func(*args, **kwargs)
  File "/usr/local/lib/python3.10/site-packages/django/db/backends/base/base.py", line 274, in ensure_connection
    with self.wrap_database_errors:
  File "/usr/local/lib/python3.10/site-packages/django/db/utils.py", line 91, in __exit__
    raise dj_exc_value.with_traceback(traceback) from exc_value
  File "/usr/local/lib/python3.10/site-packages/django/db/backends/base/base.py", line 275, in ensure_connection
    self.connect()
  File "/usr/local/lib/python3.10/site-packages/django/utils/asyncio.py", line 26, in inner
    return func(*args, **kwargs)
  File "/usr/local/lib/python3.10/site-packages/django/db/backends/base/base.py", line 256, in connect
    self.connection = self.get_new_connection(conn_params)
  File "/usr/local/lib/python3.10/site-packages/django/utils/asyncio.py", line 26, in inner
    return func(*args, **kwargs)
  File "/usr/local/lib/python3.10/site-packages/django/db/backends/postgresql/base.py", line 277, in get_new_connection
    connection = self.Database.connect(**conn_params)
  File "/usr/local/lib/python3.10/site-packages/psycopg2/__init__.py", line 122, in connect
    conn = _connect(dsn, connection_factory=connection_factory, **kwasync)
django.db.utils.OperationalError: connection to server at "localhost" (127.0.0.1), port 5432 failed: Connection refused
	Is the server running on that host and accepting TCP/IP connections?
connection to server at "localhost" (::1), port 5432 failed: Cannot assign requested address
	Is the server running on that host and accepting TCP/IP connections?

[2024-03-26 06:18:00,015: INFO/MainProcess] Task tracker.tasks.cel_scraper[f9d0dc51-7427-4952-be56-7e4ca6f900c5] received
[2024-03-26 06:18:00,046: ERROR/MainProcess] Task tracker.tasks.cel_scraper[f9d0dc51-7427-4952-be56-7e4ca6f900c5] raised unexpected: OperationalError('connection to server at "localhost" (127.0.0.1), port 5432 failed: Connection refused\n\tIs the server running on that host and accepting TCP/IP connections?\nconnection to server at "localhost" (::1), port 5432 failed: Cannot assign requested address\n\tIs the server running on that host and accepting TCP/IP connections?\n')
Traceback (most recent call last):
  File "/usr/local/lib/python3.10/site-packages/django/db/backends/base/base.py", line 275, in ensure_connection
    self.connect()
  File "/usr/local/lib/python3.10/site-packages/django/utils/asyncio.py", line 26, in inner
    return func(*args, **kwargs)
  File "/usr/local/lib/python3.10/site-packages/django/db/backends/base/base.py", line 256, in connect
    self.connection = self.get_new_connection(conn_params)
  File "/usr/local/lib/python3.10/site-packages/django/utils/asyncio.py", line 26, in inner
    return func(*args, **kwargs)
  File "/usr/local/lib/python3.10/site-packages/django/db/backends/postgresql/base.py", line 277, in get_new_connection
    connection = self.Database.connect(**conn_params)
  File "/usr/local/lib/python3.10/site-packages/psycopg2/__init__.py", line 122, in connect
    conn = _connect(dsn, connection_factory=connection_factory, **kwasync)
psycopg2.OperationalError: connection to server at "localhost" (127.0.0.1), port 5432 failed: Connection refused
	Is the server running on that host and accepting TCP/IP connections?
connection to server at "localhost" (::1), port 5432 failed: Cannot assign requested address
	Is the server running on that host and accepting TCP/IP connections?


The above exception was the direct cause of the following exception:

Traceback (most recent call last):
  File "/usr/local/lib/python3.10/site-packages/celery/app/trace.py", line 477, in trace_task
    R = retval = fun(*args, **kwargs)
  File "/usr/local/lib/python3.10/site-packages/celery/app/trace.py", line 760, in __protected_call__
    return self.run(*args, **kwargs)
  File "/usr/src/app/tracker/tasks.py", line 14, in cel_scraper
    scraper.scrape()
  File "/usr/src/app/tracker/Utils/Scraper.py", line 21, in scrape
    for  product in urls:
  File "/usr/local/lib/python3.10/site-packages/django/db/models/query.py", line 400, in __iter__
    self._fetch_all()
  File "/usr/local/lib/python3.10/site-packages/django/db/models/query.py", line 1928, in _fetch_all
    self._result_cache = list(self._iterable_class(self))
  File "/usr/local/lib/python3.10/site-packages/django/db/models/query.py", line 91, in __iter__
    results = compiler.execute_sql(
  File "/usr/local/lib/python3.10/site-packages/django/db/models/sql/compiler.py", line 1560, in execute_sql
    cursor = self.connection.cursor()
  File "/usr/local/lib/python3.10/site-packages/django/utils/asyncio.py", line 26, in inner
    return func(*args, **kwargs)
  File "/usr/local/lib/python3.10/site-packages/django/db/backends/base/base.py", line 316, in cursor
    return self._cursor()
  File "/usr/local/lib/python3.10/site-packages/django/db/backends/base/base.py", line 292, in _cursor
    self.ensure_connection()
  File "/usr/local/lib/python3.10/site-packages/django/utils/asyncio.py", line 26, in inner
    return func(*args, **kwargs)
  File "/usr/local/lib/python3.10/site-packages/django/db/backends/base/base.py", line 274, in ensure_connection
    with self.wrap_database_errors:
  File "/usr/local/lib/python3.10/site-packages/django/db/utils.py", line 91, in __exit__
    raise dj_exc_value.with_traceback(traceback) from exc_value
  File "/usr/local/lib/python3.10/site-packages/django/db/backends/base/base.py", line 275, in ensure_connection
    self.connect()
  File "/usr/local/lib/python3.10/site-packages/django/utils/asyncio.py", line 26, in inner
    return func(*args, **kwargs)
  File "/usr/local/lib/python3.10/site-packages/django/db/backends/base/base.py", line 256, in connect
    self.connection = self.get_new_connection(conn_params)
  File "/usr/local/lib/python3.10/site-packages/django/utils/asyncio.py", line 26, in inner
    return func(*args, **kwargs)
  File "/usr/local/lib/python3.10/site-packages/django/db/backends/postgresql/base.py", line 277, in get_new_connection
    connection = self.Database.connect(**conn_params)
  File "/usr/local/lib/python3.10/site-packages/psycopg2/__init__.py", line 122, in connect
    conn = _connect(dsn, connection_factory=connection_factory, **kwasync)
django.db.utils.OperationalError: connection to server at "localhost" (127.0.0.1), port 5432 failed: Connection refused
	Is the server running on that host and accepting TCP/IP connections?
connection to server at "localhost" (::1), port 5432 failed: Cannot assign requested address
	Is the server running on that host and accepting TCP/IP connections?

[2024-03-26 06:19:00,055: INFO/MainProcess] Task tracker.tasks.cel_scraper[91c748ab-4d20-4866-a991-564ec9814dd9] received
[2024-03-26 06:19:00,106: ERROR/MainProcess] Task tracker.tasks.cel_scraper[91c748ab-4d20-4866-a991-564ec9814dd9] raised unexpected: OperationalError('connection to server at "localhost" (127.0.0.1), port 5432 failed: Connection refused\n\tIs the server running on that host and accepting TCP/IP connections?\nconnection to server at "localhost" (::1), port 5432 failed: Cannot assign requested address\n\tIs the server running on that host and accepting TCP/IP connections?\n')
Traceback (most recent call last):
  File "/usr/local/lib/python3.10/site-packages/django/db/backends/base/base.py", line 275, in ensure_connection
    self.connect()
  File "/usr/local/lib/python3.10/site-packages/django/utils/asyncio.py", line 26, in inner
    return func(*args, **kwargs)
  File "/usr/local/lib/python3.10/site-packages/django/db/backends/base/base.py", line 256, in connect
    self.connection = self.get_new_connection(conn_params)
  File "/usr/local/lib/python3.10/site-packages/django/utils/asyncio.py", line 26, in inner
    return func(*args, **kwargs)
  File "/usr/local/lib/python3.10/site-packages/django/db/backends/postgresql/base.py", line 277, in get_new_connection
    connection = self.Database.connect(**conn_params)
  File "/usr/local/lib/python3.10/site-packages/psycopg2/__init__.py", line 122, in connect
    conn = _connect(dsn, connection_factory=connection_factory, **kwasync)
psycopg2.OperationalError: connection to server at "localhost" (127.0.0.1), port 5432 failed: Connection refused
	Is the server running on that host and accepting TCP/IP connections?
connection to server at "localhost" (::1), port 5432 failed: Cannot assign requested address
	Is the server running on that host and accepting TCP/IP connections?


The above exception was the direct cause of the following exception:

Traceback (most recent call last):
  File "/usr/local/lib/python3.10/site-packages/celery/app/trace.py", line 477, in trace_task
    R = retval = fun(*args, **kwargs)
  File "/usr/local/lib/python3.10/site-packages/celery/app/trace.py", line 760, in __protected_call__
    return self.run(*args, **kwargs)
  File "/usr/src/app/tracker/tasks.py", line 14, in cel_scraper
    scraper.scrape()
  File "/usr/src/app/tracker/Utils/Scraper.py", line 21, in scrape
    for  product in urls:
  File "/usr/local/lib/python3.10/site-packages/django/db/models/query.py", line 400, in __iter__
    self._fetch_all()
  File "/usr/local/lib/python3.10/site-packages/django/db/models/query.py", line 1928, in _fetch_all
    self._result_cache = list(self._iterable_class(self))
  File "/usr/local/lib/python3.10/site-packages/django/db/models/query.py", line 91, in __iter__
    results = compiler.execute_sql(
  File "/usr/local/lib/python3.10/site-packages/django/db/models/sql/compiler.py", line 1560, in execute_sql
    cursor = self.connection.cursor()
  File "/usr/local/lib/python3.10/site-packages/django/utils/asyncio.py", line 26, in inner
    return func(*args, **kwargs)
  File "/usr/local/lib/python3.10/site-packages/django/db/backends/base/base.py", line 316, in cursor
    return self._cursor()
  File "/usr/local/lib/python3.10/site-packages/django/db/backends/base/base.py", line 292, in _cursor
    self.ensure_connection()
  File "/usr/local/lib/python3.10/site-packages/django/utils/asyncio.py", line 26, in inner
    return func(*args, **kwargs)
  File "/usr/local/lib/python3.10/site-packages/django/db/backends/base/base.py", line 274, in ensure_connection
    with self.wrap_database_errors:
  File "/usr/local/lib/python3.10/site-packages/django/db/utils.py", line 91, in __exit__
    raise dj_exc_value.with_traceback(traceback) from exc_value
  File "/usr/local/lib/python3.10/site-packages/django/db/backends/base/base.py", line 275, in ensure_connection
    self.connect()
  File "/usr/local/lib/python3.10/site-packages/django/utils/asyncio.py", line 26, in inner
    return func(*args, **kwargs)
  File "/usr/local/lib/python3.10/site-packages/django/db/backends/base/base.py", line 256, in connect
    self.connection = self.get_new_connection(conn_params)
  File "/usr/local/lib/python3.10/site-packages/django/utils/asyncio.py", line 26, in inner
    return func(*args, **kwargs)
  File "/usr/local/lib/python3.10/site-packages/django/db/backends/postgresql/base.py", line 277, in get_new_connection
    connection = self.Database.connect(**conn_params)
  File "/usr/local/lib/python3.10/site-packages/psycopg2/__init__.py", line 122, in connect
    conn = _connect(dsn, connection_factory=connection_factory, **kwasync)
django.db.utils.OperationalError: connection to server at "localhost" (127.0.0.1), port 5432 failed: Connection refused
	Is the server running on that host and accepting TCP/IP connections?
connection to server at "localhost" (::1), port 5432 failed: Cannot assign requested address
	Is the server running on that host and accepting TCP/IP connections?

[2024-03-26 06:20:00,062: INFO/MainProcess] Task tracker.tasks.cel_scraper[32ecbab5-3436-41df-938c-2fe7e27bbedf] received
[2024-03-26 06:20:00,073: ERROR/MainProcess] Task tracker.tasks.cel_scraper[32ecbab5-3436-41df-938c-2fe7e27bbedf] raised unexpected: OperationalError('connection to server at "localhost" (127.0.0.1), port 5432 failed: Connection refused\n\tIs the server running on that host and accepting TCP/IP connections?\nconnection to server at "localhost" (::1), port 5432 failed: Cannot assign requested address\n\tIs the server running on that host and accepting TCP/IP connections?\n')
Traceback (most recent call last):
  File "/usr/local/lib/python3.10/site-packages/django/db/backends/base/base.py", line 275, in ensure_connection
    self.connect()
  File "/usr/local/lib/python3.10/site-packages/django/utils/asyncio.py", line 26, in inner
    return func(*args, **kwargs)
  File "/usr/local/lib/python3.10/site-packages/django/db/backends/base/base.py", line 256, in connect
    self.connection = self.get_new_connection(conn_params)
  File "/usr/local/lib/python3.10/site-packages/django/utils/asyncio.py", line 26, in inner
    return func(*args, **kwargs)
  File "/usr/local/lib/python3.10/site-packages/django/db/backends/postgresql/base.py", line 277, in get_new_connection
    connection = self.Database.connect(**conn_params)
  File "/usr/local/lib/python3.10/site-packages/psycopg2/__init__.py", line 122, in connect
    conn = _connect(dsn, connection_factory=connection_factory, **kwasync)
psycopg2.OperationalError: connection to server at "localhost" (127.0.0.1), port 5432 failed: Connection refused
	Is the server running on that host and accepting TCP/IP connections?
connection to server at "localhost" (::1), port 5432 failed: Cannot assign requested address
	Is the server running on that host and accepting TCP/IP connections?


The above exception was the direct cause of the following exception:

Traceback (most recent call last):
  File "/usr/local/lib/python3.10/site-packages/celery/app/trace.py", line 477, in trace_task
    R = retval = fun(*args, **kwargs)
  File "/usr/local/lib/python3.10/site-packages/celery/app/trace.py", line 760, in __protected_call__
    return self.run(*args, **kwargs)
  File "/usr/src/app/tracker/tasks.py", line 14, in cel_scraper
    scraper.scrape()
  File "/usr/src/app/tracker/Utils/Scraper.py", line 21, in scrape
    for  product in urls:
  File "/usr/local/lib/python3.10/site-packages/django/db/models/query.py", line 400, in __iter__
    self._fetch_all()
  File "/usr/local/lib/python3.10/site-packages/django/db/models/query.py", line 1928, in _fetch_all
    self._result_cache = list(self._iterable_class(self))
  File "/usr/local/lib/python3.10/site-packages/django/db/models/query.py", line 91, in __iter__
    results = compiler.execute_sql(
  File "/usr/local/lib/python3.10/site-packages/django/db/models/sql/compiler.py", line 1560, in execute_sql
    cursor = self.connection.cursor()
  File "/usr/local/lib/python3.10/site-packages/django/utils/asyncio.py", line 26, in inner
    return func(*args, **kwargs)
  File "/usr/local/lib/python3.10/site-packages/django/db/backends/base/base.py", line 316, in cursor
    return self._cursor()
  File "/usr/local/lib/python3.10/site-packages/django/db/backends/base/base.py", line 292, in _cursor
    self.ensure_connection()
  File "/usr/local/lib/python3.10/site-packages/django/utils/asyncio.py", line 26, in inner
    return func(*args, **kwargs)
  File "/usr/local/lib/python3.10/site-packages/django/db/backends/base/base.py", line 274, in ensure_connection
    with self.wrap_database_errors:
  File "/usr/local/lib/python3.10/site-packages/django/db/utils.py", line 91, in __exit__
    raise dj_exc_value.with_traceback(traceback) from exc_value
  File "/usr/local/lib/python3.10/site-packages/django/db/backends/base/base.py", line 275, in ensure_connection
    self.connect()
  File "/usr/local/lib/python3.10/site-packages/django/utils/asyncio.py", line 26, in inner
    return func(*args, **kwargs)
  File "/usr/local/lib/python3.10/site-packages/django/db/backends/base/base.py", line 256, in connect
    self.connection = self.get_new_connection(conn_params)
  File "/usr/local/lib/python3.10/site-packages/django/utils/asyncio.py", line 26, in inner
    return func(*args, **kwargs)
  File "/usr/local/lib/python3.10/site-packages/django/db/backends/postgresql/base.py", line 277, in get_new_connection
    connection = self.Database.connect(**conn_params)
  File "/usr/local/lib/python3.10/site-packages/psycopg2/__init__.py", line 122, in connect
    conn = _connect(dsn, connection_factory=connection_factory, **kwasync)
django.db.utils.OperationalError: connection to server at "localhost" (127.0.0.1), port 5432 failed: Connection refused
	Is the server running on that host and accepting TCP/IP connections?
connection to server at "localhost" (::1), port 5432 failed: Cannot assign requested address
	Is the server running on that host and accepting TCP/IP connections?

[2024-03-26 06:20:19,079: WARNING/MainProcess] /usr/local/lib/python3.10/site-packages/celery/worker/consumer/consumer.py:507: CPendingDeprecationWarning: The broker_connection_retry configuration setting will no longer determine
whether broker connection retries are made during startup in Celery 6.0 and above.
If you wish to retain the existing behavior for retrying connections on startup,
you should set broker_connection_retry_on_startup to True.
  warnings.warn(

[2024-03-26 06:20:19,090: INFO/MainProcess] Connected to redis://redis:6379/0
[2024-03-26 06:20:19,092: WARNING/MainProcess] /usr/local/lib/python3.10/site-packages/celery/worker/consumer/consumer.py:507: CPendingDeprecationWarning: The broker_connection_retry configuration setting will no longer determine
whether broker connection retries are made during startup in Celery 6.0 and above.
If you wish to retain the existing behavior for retrying connections on startup,
you should set broker_connection_retry_on_startup to True.
  warnings.warn(

[2024-03-26 06:20:19,095: INFO/MainProcess] mingle: searching for neighbors
[2024-03-26 06:20:20,108: INFO/MainProcess] mingle: all alone
[2024-03-26 06:20:20,128: INFO/MainProcess] celery@b12a0793993f ready.
[2024-03-26 06:20:23,591: INFO/MainProcess] Events of group {task} enabled by remote.
[2024-03-26 06:21:00,064: INFO/MainProcess] Task tracker.tasks.cel_scraper[db3dbf38-8085-4a75-8075-25690398dc01] received
[2024-03-26 06:21:35,649: ERROR/MainProcess] Task tracker.tasks.cel_scraper[db3dbf38-8085-4a75-8075-25690398dc01] raised unexpected: WebDriverException()
Traceback (most recent call last):
  File "/usr/local/lib/python3.10/site-packages/celery/app/trace.py", line 477, in trace_task
    R = retval = fun(*args, **kwargs)
  File "/usr/local/lib/python3.10/site-packages/celery/app/trace.py", line 760, in __protected_call__
    return self.run(*args, **kwargs)
  File "/usr/src/app/tracker/tasks.py", line 14, in cel_scraper
    scraper.scrape()
  File "/usr/src/app/tracker/Utils/Scraper.py", line 26, in scrape
    data = self.scrape_data(url)
  File "/usr/src/app/tracker/Utils/Scraper.py", line 58, in scrape_data
    browser = webdriver.Edge(options=options)
  File "/usr/local/lib/python3.10/site-packages/selenium/webdriver/edge/webdriver.py", line 45, in __init__
    super().__init__(
  File "/usr/local/lib/python3.10/site-packages/selenium/webdriver/chromium/webdriver.py", line 50, in __init__
    self.service.start()
  File "/usr/local/lib/python3.10/site-packages/selenium/webdriver/common/service.py", line 102, in start
    self.assert_process_still_running()
  File "/usr/local/lib/python3.10/site-packages/selenium/webdriver/common/service.py", line 115, in assert_process_still_running
    raise WebDriverException(f"Service {self._path} unexpectedly exited. Status code was: {return_code}")
selenium.common.exceptions.WebDriverException: Message: Service /root/.cache/selenium/msedgedriver/linux64/123.0.2420.53/msedgedriver unexpectedly exited. Status code was: 127

[2024-03-26 06:22:00,057: INFO/MainProcess] Task tracker.tasks.cel_scraper[40e76f4e-cdfe-4656-afa2-be4fd46da96a] received
[2024-03-26 06:22:00,140: ERROR/MainProcess] Task tracker.tasks.cel_scraper[40e76f4e-cdfe-4656-afa2-be4fd46da96a] raised unexpected: WebDriverException()
Traceback (most recent call last):
  File "/usr/local/lib/python3.10/site-packages/celery/app/trace.py", line 477, in trace_task
    R = retval = fun(*args, **kwargs)
  File "/usr/local/lib/python3.10/site-packages/celery/app/trace.py", line 760, in __protected_call__
    return self.run(*args, **kwargs)
  File "/usr/src/app/tracker/tasks.py", line 14, in cel_scraper
    scraper.scrape()
  File "/usr/src/app/tracker/Utils/Scraper.py", line 26, in scrape
    data = self.scrape_data(url)
  File "/usr/src/app/tracker/Utils/Scraper.py", line 58, in scrape_data
    browser = webdriver.Edge(options=options)
  File "/usr/local/lib/python3.10/site-packages/selenium/webdriver/edge/webdriver.py", line 45, in __init__
    super().__init__(
  File "/usr/local/lib/python3.10/site-packages/selenium/webdriver/chromium/webdriver.py", line 50, in __init__
    self.service.start()
  File "/usr/local/lib/python3.10/site-packages/selenium/webdriver/common/service.py", line 102, in start
    self.assert_process_still_running()
  File "/usr/local/lib/python3.10/site-packages/selenium/webdriver/common/service.py", line 115, in assert_process_still_running
    raise WebDriverException(f"Service {self._path} unexpectedly exited. Status code was: {return_code}")
selenium.common.exceptions.WebDriverException: Message: Service /root/.cache/selenium/msedgedriver/linux64/123.0.2420.53/msedgedriver unexpectedly exited. Status code was: 127

[2024-03-26 06:22:51,060: WARNING/MainProcess] /usr/local/lib/python3.10/site-packages/celery/worker/consumer/consumer.py:507: CPendingDeprecationWarning: The broker_connection_retry configuration setting will no longer determine
whether broker connection retries are made during startup in Celery 6.0 and above.
If you wish to retain the existing behavior for retrying connections on startup,
you should set broker_connection_retry_on_startup to True.
  warnings.warn(

[2024-03-26 06:22:51,078: INFO/MainProcess] Connected to redis://redis:6379/0
[2024-03-26 06:22:51,081: WARNING/MainProcess] /usr/local/lib/python3.10/site-packages/celery/worker/consumer/consumer.py:507: CPendingDeprecationWarning: The broker_connection_retry configuration setting will no longer determine
whether broker connection retries are made during startup in Celery 6.0 and above.
If you wish to retain the existing behavior for retrying connections on startup,
you should set broker_connection_retry_on_startup to True.
  warnings.warn(

[2024-03-26 06:22:51,090: INFO/MainProcess] mingle: searching for neighbors
[2024-03-26 06:22:52,106: INFO/MainProcess] mingle: all alone
[2024-03-26 06:22:52,122: INFO/MainProcess] celery@9ce602c92cc4 ready.
[2024-03-26 06:22:54,974: INFO/MainProcess] Events of group {task} enabled by remote.
[2024-03-26 06:23:00,029: INFO/MainProcess] Task tracker.tasks.cel_scraper[e2b7c366-7470-4199-ad29-81fee864047b] received
[2024-03-26 06:23:30,229: ERROR/MainProcess] Task tracker.tasks.cel_scraper[e2b7c366-7470-4199-ad29-81fee864047b] raised unexpected: WebDriverException()
Traceback (most recent call last):
  File "/usr/local/lib/python3.10/site-packages/celery/app/trace.py", line 477, in trace_task
    R = retval = fun(*args, **kwargs)
  File "/usr/local/lib/python3.10/site-packages/celery/app/trace.py", line 760, in __protected_call__
    return self.run(*args, **kwargs)
  File "/usr/src/app/tracker/tasks.py", line 14, in cel_scraper
    scraper.scrape()
  File "/usr/src/app/tracker/Utils/Scraper.py", line 26, in scrape
    data = self.scrape_data(url)
  File "/usr/src/app/tracker/Utils/Scraper.py", line 58, in scrape_data
    browser = webdriver.Edge(options=options)
  File "/usr/local/lib/python3.10/site-packages/selenium/webdriver/edge/webdriver.py", line 45, in __init__
    super().__init__(
  File "/usr/local/lib/python3.10/site-packages/selenium/webdriver/chromium/webdriver.py", line 50, in __init__
    self.service.start()
  File "/usr/local/lib/python3.10/site-packages/selenium/webdriver/common/service.py", line 102, in start
    self.assert_process_still_running()
  File "/usr/local/lib/python3.10/site-packages/selenium/webdriver/common/service.py", line 115, in assert_process_still_running
    raise WebDriverException(f"Service {self._path} unexpectedly exited. Status code was: {return_code}")
selenium.common.exceptions.WebDriverException: Message: Service /root/.cache/selenium/msedgedriver/linux64/123.0.2420.53/msedgedriver unexpectedly exited. Status code was: 127

[2024-03-26 06:24:50,262: WARNING/MainProcess] /usr/local/lib/python3.10/site-packages/celery/worker/consumer/consumer.py:507: CPendingDeprecationWarning: The broker_connection_retry configuration setting will no longer determine
whether broker connection retries are made during startup in Celery 6.0 and above.
If you wish to retain the existing behavior for retrying connections on startup,
you should set broker_connection_retry_on_startup to True.
  warnings.warn(

[2024-03-26 06:24:50,275: INFO/MainProcess] Connected to redis://redis:6379/0
[2024-03-26 06:24:50,276: WARNING/MainProcess] /usr/local/lib/python3.10/site-packages/celery/worker/consumer/consumer.py:507: CPendingDeprecationWarning: The broker_connection_retry configuration setting will no longer determine
whether broker connection retries are made during startup in Celery 6.0 and above.
If you wish to retain the existing behavior for retrying connections on startup,
you should set broker_connection_retry_on_startup to True.
  warnings.warn(

[2024-03-26 06:24:50,283: INFO/MainProcess] mingle: searching for neighbors
[2024-03-26 06:24:51,296: INFO/MainProcess] mingle: all alone
[2024-03-26 06:24:51,313: INFO/MainProcess] celery@c68dc0fb638d ready.
[2024-03-26 06:24:51,316: INFO/MainProcess] Task tracker.tasks.cel_scraper[ca397224-9253-4775-af25-47615e508a80] received
[2024-03-26 06:25:46,435: ERROR/MainProcess] Task tracker.tasks.cel_scraper[ca397224-9253-4775-af25-47615e508a80] raised unexpected: WebDriverException()
Traceback (most recent call last):
  File "/usr/local/lib/python3.10/site-packages/celery/app/trace.py", line 477, in trace_task
    R = retval = fun(*args, **kwargs)
  File "/usr/local/lib/python3.10/site-packages/celery/app/trace.py", line 760, in __protected_call__
    return self.run(*args, **kwargs)
  File "/usr/src/app/tracker/tasks.py", line 14, in cel_scraper
    scraper.scrape()
  File "/usr/src/app/tracker/Utils/Scraper.py", line 26, in scrape
    data = self.scrape_data(url)
  File "/usr/src/app/tracker/Utils/Scraper.py", line 58, in scrape_data
    browser = webdriver.Edge(options=options)
  File "/usr/local/lib/python3.10/site-packages/selenium/webdriver/edge/webdriver.py", line 45, in __init__
    super().__init__(
  File "/usr/local/lib/python3.10/site-packages/selenium/webdriver/chromium/webdriver.py", line 50, in __init__
    self.service.start()
  File "/usr/local/lib/python3.10/site-packages/selenium/webdriver/common/service.py", line 102, in start
    self.assert_process_still_running()
  File "/usr/local/lib/python3.10/site-packages/selenium/webdriver/common/service.py", line 115, in assert_process_still_running
    raise WebDriverException(f"Service {self._path} unexpectedly exited. Status code was: {return_code}")
selenium.common.exceptions.WebDriverException: Message: Service /root/.cache/selenium/msedgedriver/linux64/123.0.2420.53/msedgedriver unexpectedly exited. Status code was: 127

[2024-03-26 06:25:46,673: INFO/MainProcess] Task tracker.tasks.cel_scraper[e7416095-9d35-49f3-b898-74bb4c11e628] received
[2024-03-26 06:25:46,866: ERROR/MainProcess] Task tracker.tasks.cel_scraper[e7416095-9d35-49f3-b898-74bb4c11e628] raised unexpected: WebDriverException()
Traceback (most recent call last):
  File "/usr/local/lib/python3.10/site-packages/celery/app/trace.py", line 477, in trace_task
    R = retval = fun(*args, **kwargs)
  File "/usr/local/lib/python3.10/site-packages/celery/app/trace.py", line 760, in __protected_call__
    return self.run(*args, **kwargs)
  File "/usr/src/app/tracker/tasks.py", line 14, in cel_scraper
    scraper.scrape()
  File "/usr/src/app/tracker/Utils/Scraper.py", line 26, in scrape
    data = self.scrape_data(url)
  File "/usr/src/app/tracker/Utils/Scraper.py", line 58, in scrape_data
    browser = webdriver.Edge(options=options)
  File "/usr/local/lib/python3.10/site-packages/selenium/webdriver/edge/webdriver.py", line 45, in __init__
    super().__init__(
  File "/usr/local/lib/python3.10/site-packages/selenium/webdriver/chromium/webdriver.py", line 50, in __init__
    self.service.start()
  File "/usr/local/lib/python3.10/site-packages/selenium/webdriver/common/service.py", line 102, in start
    self.assert_process_still_running()
  File "/usr/local/lib/python3.10/site-packages/selenium/webdriver/common/service.py", line 115, in assert_process_still_running
    raise WebDriverException(f"Service {self._path} unexpectedly exited. Status code was: {return_code}")
selenium.common.exceptions.WebDriverException: Message: Service /root/.cache/selenium/msedgedriver/linux64/123.0.2420.53/msedgedriver unexpectedly exited. Status code was: 127

[2024-03-26 06:25:46,878: INFO/MainProcess] Events of group {task} enabled by remote.
[2024-03-26 06:26:00,075: INFO/MainProcess] Task tracker.tasks.cel_scraper[a0da5f99-5077-4b3f-b984-f7b1f4feafac] received
[2024-03-26 06:26:00,178: ERROR/MainProcess] Task tracker.tasks.cel_scraper[a0da5f99-5077-4b3f-b984-f7b1f4feafac] raised unexpected: WebDriverException()
Traceback (most recent call last):
  File "/usr/local/lib/python3.10/site-packages/celery/app/trace.py", line 477, in trace_task
    R = retval = fun(*args, **kwargs)
  File "/usr/local/lib/python3.10/site-packages/celery/app/trace.py", line 760, in __protected_call__
    return self.run(*args, **kwargs)
  File "/usr/src/app/tracker/tasks.py", line 14, in cel_scraper
    scraper.scrape()
  File "/usr/src/app/tracker/Utils/Scraper.py", line 26, in scrape
    data = self.scrape_data(url)
  File "/usr/src/app/tracker/Utils/Scraper.py", line 58, in scrape_data
    browser = webdriver.Edge(options=options)
  File "/usr/local/lib/python3.10/site-packages/selenium/webdriver/edge/webdriver.py", line 45, in __init__
    super().__init__(
  File "/usr/local/lib/python3.10/site-packages/selenium/webdriver/chromium/webdriver.py", line 50, in __init__
    self.service.start()
  File "/usr/local/lib/python3.10/site-packages/selenium/webdriver/common/service.py", line 102, in start
    self.assert_process_still_running()
  File "/usr/local/lib/python3.10/site-packages/selenium/webdriver/common/service.py", line 115, in assert_process_still_running
    raise WebDriverException(f"Service {self._path} unexpectedly exited. Status code was: {return_code}")
selenium.common.exceptions.WebDriverException: Message: Service /root/.cache/selenium/msedgedriver/linux64/123.0.2420.53/msedgedriver unexpectedly exited. Status code was: 127

[2024-03-26 06:27:00,120: INFO/MainProcess] Task tracker.tasks.cel_scraper[426b096e-7e49-4a08-bdb1-2d9ffa483a16] received
[2024-03-26 06:27:00,300: ERROR/MainProcess] Task tracker.tasks.cel_scraper[426b096e-7e49-4a08-bdb1-2d9ffa483a16] raised unexpected: WebDriverException()
Traceback (most recent call last):
  File "/usr/local/lib/python3.10/site-packages/celery/app/trace.py", line 477, in trace_task
    R = retval = fun(*args, **kwargs)
  File "/usr/local/lib/python3.10/site-packages/celery/app/trace.py", line 760, in __protected_call__
    return self.run(*args, **kwargs)
  File "/usr/src/app/tracker/tasks.py", line 14, in cel_scraper
    scraper.scrape()
  File "/usr/src/app/tracker/Utils/Scraper.py", line 26, in scrape
    data = self.scrape_data(url)
  File "/usr/src/app/tracker/Utils/Scraper.py", line 58, in scrape_data
    browser = webdriver.Edge(options=options)
  File "/usr/local/lib/python3.10/site-packages/selenium/webdriver/edge/webdriver.py", line 45, in __init__
    super().__init__(
  File "/usr/local/lib/python3.10/site-packages/selenium/webdriver/chromium/webdriver.py", line 50, in __init__
    self.service.start()
  File "/usr/local/lib/python3.10/site-packages/selenium/webdriver/common/service.py", line 102, in start
    self.assert_process_still_running()
  File "/usr/local/lib/python3.10/site-packages/selenium/webdriver/common/service.py", line 115, in assert_process_still_running
    raise WebDriverException(f"Service {self._path} unexpectedly exited. Status code was: {return_code}")
selenium.common.exceptions.WebDriverException: Message: Service /root/.cache/selenium/msedgedriver/linux64/123.0.2420.53/msedgedriver unexpectedly exited. Status code was: 127

[2024-03-26 06:28:00,572: INFO/MainProcess] Task tracker.tasks.cel_scraper[390cb9be-e765-427a-b708-90abb0dc1192] received
[2024-03-26 06:28:01,082: ERROR/MainProcess] Task tracker.tasks.cel_scraper[390cb9be-e765-427a-b708-90abb0dc1192] raised unexpected: WebDriverException()
Traceback (most recent call last):
  File "/usr/local/lib/python3.10/site-packages/celery/app/trace.py", line 477, in trace_task
    R = retval = fun(*args, **kwargs)
  File "/usr/local/lib/python3.10/site-packages/celery/app/trace.py", line 760, in __protected_call__
    return self.run(*args, **kwargs)
  File "/usr/src/app/tracker/tasks.py", line 14, in cel_scraper
    scraper.scrape()
  File "/usr/src/app/tracker/Utils/Scraper.py", line 26, in scrape
    data = self.scrape_data(url)
  File "/usr/src/app/tracker/Utils/Scraper.py", line 58, in scrape_data
    browser = webdriver.Edge(options=options)
  File "/usr/local/lib/python3.10/site-packages/selenium/webdriver/edge/webdriver.py", line 45, in __init__
    super().__init__(
  File "/usr/local/lib/python3.10/site-packages/selenium/webdriver/chromium/webdriver.py", line 50, in __init__
    self.service.start()
  File "/usr/local/lib/python3.10/site-packages/selenium/webdriver/common/service.py", line 102, in start
    self.assert_process_still_running()
  File "/usr/local/lib/python3.10/site-packages/selenium/webdriver/common/service.py", line 115, in assert_process_still_running
    raise WebDriverException(f"Service {self._path} unexpectedly exited. Status code was: {return_code}")
selenium.common.exceptions.WebDriverException: Message: Service /root/.cache/selenium/msedgedriver/linux64/123.0.2420.53/msedgedriver unexpectedly exited. Status code was: 127

[2024-03-26 06:29:00,267: INFO/MainProcess] Task tracker.tasks.cel_scraper[b3add330-cb38-4835-acfd-57eae5247f2c] received
[2024-03-26 06:29:00,868: ERROR/MainProcess] Task tracker.tasks.cel_scraper[b3add330-cb38-4835-acfd-57eae5247f2c] raised unexpected: WebDriverException()
Traceback (most recent call last):
  File "/usr/local/lib/python3.10/site-packages/celery/app/trace.py", line 477, in trace_task
    R = retval = fun(*args, **kwargs)
  File "/usr/local/lib/python3.10/site-packages/celery/app/trace.py", line 760, in __protected_call__
    return self.run(*args, **kwargs)
  File "/usr/src/app/tracker/tasks.py", line 14, in cel_scraper
    scraper.scrape()
  File "/usr/src/app/tracker/Utils/Scraper.py", line 26, in scrape
    data = self.scrape_data(url)
  File "/usr/src/app/tracker/Utils/Scraper.py", line 58, in scrape_data
    browser = webdriver.Edge(options=options)
  File "/usr/local/lib/python3.10/site-packages/selenium/webdriver/edge/webdriver.py", line 45, in __init__
    super().__init__(
  File "/usr/local/lib/python3.10/site-packages/selenium/webdriver/chromium/webdriver.py", line 50, in __init__
    self.service.start()
  File "/usr/local/lib/python3.10/site-packages/selenium/webdriver/common/service.py", line 102, in start
    self.assert_process_still_running()
  File "/usr/local/lib/python3.10/site-packages/selenium/webdriver/common/service.py", line 115, in assert_process_still_running
    raise WebDriverException(f"Service {self._path} unexpectedly exited. Status code was: {return_code}")
selenium.common.exceptions.WebDriverException: Message: Service /root/.cache/selenium/msedgedriver/linux64/123.0.2420.53/msedgedriver unexpectedly exited. Status code was: 127

[2024-03-26 06:30:00,261: INFO/MainProcess] Task tracker.tasks.cel_scraper[1be05f05-ec3a-4ca8-99b4-8149a707707c] received
[2024-03-26 06:30:00,811: ERROR/MainProcess] Task tracker.tasks.cel_scraper[1be05f05-ec3a-4ca8-99b4-8149a707707c] raised unexpected: WebDriverException()
Traceback (most recent call last):
  File "/usr/local/lib/python3.10/site-packages/celery/app/trace.py", line 477, in trace_task
    R = retval = fun(*args, **kwargs)
  File "/usr/local/lib/python3.10/site-packages/celery/app/trace.py", line 760, in __protected_call__
    return self.run(*args, **kwargs)
  File "/usr/src/app/tracker/tasks.py", line 14, in cel_scraper
    scraper.scrape()
  File "/usr/src/app/tracker/Utils/Scraper.py", line 26, in scrape
    data = self.scrape_data(url)
  File "/usr/src/app/tracker/Utils/Scraper.py", line 58, in scrape_data
    browser = webdriver.Edge(options=options)
  File "/usr/local/lib/python3.10/site-packages/selenium/webdriver/edge/webdriver.py", line 45, in __init__
    super().__init__(
  File "/usr/local/lib/python3.10/site-packages/selenium/webdriver/chromium/webdriver.py", line 50, in __init__
    self.service.start()
  File "/usr/local/lib/python3.10/site-packages/selenium/webdriver/common/service.py", line 102, in start
    self.assert_process_still_running()
  File "/usr/local/lib/python3.10/site-packages/selenium/webdriver/common/service.py", line 115, in assert_process_still_running
    raise WebDriverException(f"Service {self._path} unexpectedly exited. Status code was: {return_code}")
selenium.common.exceptions.WebDriverException: Message: Service /root/.cache/selenium/msedgedriver/linux64/123.0.2420.53/msedgedriver unexpectedly exited. Status code was: 127

[2024-03-26 06:31:00,322: INFO/MainProcess] Task tracker.tasks.cel_scraper[b1e0b516-8af4-4ed6-ac36-5bb9384bbfb4] received
[2024-03-26 06:31:01,033: ERROR/MainProcess] Task tracker.tasks.cel_scraper[b1e0b516-8af4-4ed6-ac36-5bb9384bbfb4] raised unexpected: WebDriverException()
Traceback (most recent call last):
  File "/usr/local/lib/python3.10/site-packages/celery/app/trace.py", line 477, in trace_task
    R = retval = fun(*args, **kwargs)
  File "/usr/local/lib/python3.10/site-packages/celery/app/trace.py", line 760, in __protected_call__
    return self.run(*args, **kwargs)
  File "/usr/src/app/tracker/tasks.py", line 14, in cel_scraper
    scraper.scrape()
  File "/usr/src/app/tracker/Utils/Scraper.py", line 26, in scrape
    data = self.scrape_data(url)
  File "/usr/src/app/tracker/Utils/Scraper.py", line 58, in scrape_data
    browser = webdriver.Edge(options=options)
  File "/usr/local/lib/python3.10/site-packages/selenium/webdriver/edge/webdriver.py", line 45, in __init__
    super().__init__(
  File "/usr/local/lib/python3.10/site-packages/selenium/webdriver/chromium/webdriver.py", line 50, in __init__
    self.service.start()
  File "/usr/local/lib/python3.10/site-packages/selenium/webdriver/common/service.py", line 102, in start
    self.assert_process_still_running()
  File "/usr/local/lib/python3.10/site-packages/selenium/webdriver/common/service.py", line 115, in assert_process_still_running
    raise WebDriverException(f"Service {self._path} unexpectedly exited. Status code was: {return_code}")
selenium.common.exceptions.WebDriverException: Message: Service /root/.cache/selenium/msedgedriver/linux64/123.0.2420.53/msedgedriver unexpectedly exited. Status code was: 127

[2024-03-26 06:32:00,067: INFO/MainProcess] Task tracker.tasks.cel_scraper[df6d57be-cc83-4796-ab3c-8534710d4a3d] received
[2024-03-26 06:32:00,181: ERROR/MainProcess] Task tracker.tasks.cel_scraper[df6d57be-cc83-4796-ab3c-8534710d4a3d] raised unexpected: WebDriverException()
Traceback (most recent call last):
  File "/usr/local/lib/python3.10/site-packages/celery/app/trace.py", line 477, in trace_task
    R = retval = fun(*args, **kwargs)
  File "/usr/local/lib/python3.10/site-packages/celery/app/trace.py", line 760, in __protected_call__
    return self.run(*args, **kwargs)
  File "/usr/src/app/tracker/tasks.py", line 14, in cel_scraper
    scraper.scrape()
  File "/usr/src/app/tracker/Utils/Scraper.py", line 26, in scrape
    data = self.scrape_data(url)
  File "/usr/src/app/tracker/Utils/Scraper.py", line 58, in scrape_data
    browser = webdriver.Edge(options=options)
  File "/usr/local/lib/python3.10/site-packages/selenium/webdriver/edge/webdriver.py", line 45, in __init__
    super().__init__(
  File "/usr/local/lib/python3.10/site-packages/selenium/webdriver/chromium/webdriver.py", line 50, in __init__
    self.service.start()
  File "/usr/local/lib/python3.10/site-packages/selenium/webdriver/common/service.py", line 102, in start
    self.assert_process_still_running()
  File "/usr/local/lib/python3.10/site-packages/selenium/webdriver/common/service.py", line 115, in assert_process_still_running
    raise WebDriverException(f"Service {self._path} unexpectedly exited. Status code was: {return_code}")
selenium.common.exceptions.WebDriverException: Message: Service /root/.cache/selenium/msedgedriver/linux64/123.0.2420.53/msedgedriver unexpectedly exited. Status code was: 127

[2024-03-26 06:33:00,012: INFO/MainProcess] Task tracker.tasks.cel_scraper[14969b75-2d15-422c-934e-d03d75e48f1e] received
[2024-03-26 06:33:00,106: ERROR/MainProcess] Task tracker.tasks.cel_scraper[14969b75-2d15-422c-934e-d03d75e48f1e] raised unexpected: WebDriverException()
Traceback (most recent call last):
  File "/usr/local/lib/python3.10/site-packages/celery/app/trace.py", line 477, in trace_task
    R = retval = fun(*args, **kwargs)
  File "/usr/local/lib/python3.10/site-packages/celery/app/trace.py", line 760, in __protected_call__
    return self.run(*args, **kwargs)
  File "/usr/src/app/tracker/tasks.py", line 14, in cel_scraper
    scraper.scrape()
  File "/usr/src/app/tracker/Utils/Scraper.py", line 26, in scrape
    data = self.scrape_data(url)
  File "/usr/src/app/tracker/Utils/Scraper.py", line 58, in scrape_data
    browser = webdriver.Edge(options=options)
  File "/usr/local/lib/python3.10/site-packages/selenium/webdriver/edge/webdriver.py", line 45, in __init__
    super().__init__(
  File "/usr/local/lib/python3.10/site-packages/selenium/webdriver/chromium/webdriver.py", line 50, in __init__
    self.service.start()
  File "/usr/local/lib/python3.10/site-packages/selenium/webdriver/common/service.py", line 102, in start
    self.assert_process_still_running()
  File "/usr/local/lib/python3.10/site-packages/selenium/webdriver/common/service.py", line 115, in assert_process_still_running
    raise WebDriverException(f"Service {self._path} unexpectedly exited. Status code was: {return_code}")
selenium.common.exceptions.WebDriverException: Message: Service /root/.cache/selenium/msedgedriver/linux64/123.0.2420.53/msedgedriver unexpectedly exited. Status code was: 127

[2024-03-26 06:34:00,052: INFO/MainProcess] Task tracker.tasks.cel_scraper[58efc3a6-c226-4eba-8499-54bfe5ff4c80] received
[2024-03-26 06:34:00,167: ERROR/MainProcess] Task tracker.tasks.cel_scraper[58efc3a6-c226-4eba-8499-54bfe5ff4c80] raised unexpected: WebDriverException()
Traceback (most recent call last):
  File "/usr/local/lib/python3.10/site-packages/celery/app/trace.py", line 477, in trace_task
    R = retval = fun(*args, **kwargs)
  File "/usr/local/lib/python3.10/site-packages/celery/app/trace.py", line 760, in __protected_call__
    return self.run(*args, **kwargs)
  File "/usr/src/app/tracker/tasks.py", line 14, in cel_scraper
    scraper.scrape()
  File "/usr/src/app/tracker/Utils/Scraper.py", line 26, in scrape
    data = self.scrape_data(url)
  File "/usr/src/app/tracker/Utils/Scraper.py", line 58, in scrape_data
    browser = webdriver.Edge(options=options)
  File "/usr/local/lib/python3.10/site-packages/selenium/webdriver/edge/webdriver.py", line 45, in __init__
    super().__init__(
  File "/usr/local/lib/python3.10/site-packages/selenium/webdriver/chromium/webdriver.py", line 50, in __init__
    self.service.start()
  File "/usr/local/lib/python3.10/site-packages/selenium/webdriver/common/service.py", line 102, in start
    self.assert_process_still_running()
  File "/usr/local/lib/python3.10/site-packages/selenium/webdriver/common/service.py", line 115, in assert_process_still_running
    raise WebDriverException(f"Service {self._path} unexpectedly exited. Status code was: {return_code}")
selenium.common.exceptions.WebDriverException: Message: Service /root/.cache/selenium/msedgedriver/linux64/123.0.2420.53/msedgedriver unexpectedly exited. Status code was: 127

[2024-03-26 06:35:00,068: INFO/MainProcess] Task tracker.tasks.cel_scraper[d96a6f64-a39d-4aac-887b-9137bf0f4d79] received
[2024-03-26 06:35:00,195: ERROR/MainProcess] Task tracker.tasks.cel_scraper[d96a6f64-a39d-4aac-887b-9137bf0f4d79] raised unexpected: WebDriverException()
Traceback (most recent call last):
  File "/usr/local/lib/python3.10/site-packages/celery/app/trace.py", line 477, in trace_task
    R = retval = fun(*args, **kwargs)
  File "/usr/local/lib/python3.10/site-packages/celery/app/trace.py", line 760, in __protected_call__
    return self.run(*args, **kwargs)
  File "/usr/src/app/tracker/tasks.py", line 14, in cel_scraper
    scraper.scrape()
  File "/usr/src/app/tracker/Utils/Scraper.py", line 26, in scrape
    data = self.scrape_data(url)
  File "/usr/src/app/tracker/Utils/Scraper.py", line 58, in scrape_data
    browser = webdriver.Edge(options=options)
  File "/usr/local/lib/python3.10/site-packages/selenium/webdriver/edge/webdriver.py", line 45, in __init__
    super().__init__(
  File "/usr/local/lib/python3.10/site-packages/selenium/webdriver/chromium/webdriver.py", line 50, in __init__
    self.service.start()
  File "/usr/local/lib/python3.10/site-packages/selenium/webdriver/common/service.py", line 102, in start
    self.assert_process_still_running()
  File "/usr/local/lib/python3.10/site-packages/selenium/webdriver/common/service.py", line 115, in assert_process_still_running
    raise WebDriverException(f"Service {self._path} unexpectedly exited. Status code was: {return_code}")
selenium.common.exceptions.WebDriverException: Message: Service /root/.cache/selenium/msedgedriver/linux64/123.0.2420.53/msedgedriver unexpectedly exited. Status code was: 127

[2024-03-26 06:36:00,054: INFO/MainProcess] Task tracker.tasks.cel_scraper[b87139f5-3631-4dc6-87aa-66edf8babf82] received
[2024-03-26 06:36:00,139: ERROR/MainProcess] Task tracker.tasks.cel_scraper[b87139f5-3631-4dc6-87aa-66edf8babf82] raised unexpected: WebDriverException()
Traceback (most recent call last):
  File "/usr/local/lib/python3.10/site-packages/celery/app/trace.py", line 477, in trace_task
    R = retval = fun(*args, **kwargs)
  File "/usr/local/lib/python3.10/site-packages/celery/app/trace.py", line 760, in __protected_call__
    return self.run(*args, **kwargs)
  File "/usr/src/app/tracker/tasks.py", line 14, in cel_scraper
    scraper.scrape()
  File "/usr/src/app/tracker/Utils/Scraper.py", line 26, in scrape
    data = self.scrape_data(url)
  File "/usr/src/app/tracker/Utils/Scraper.py", line 58, in scrape_data
    browser = webdriver.Edge(options=options)
  File "/usr/local/lib/python3.10/site-packages/selenium/webdriver/edge/webdriver.py", line 45, in __init__
    super().__init__(
  File "/usr/local/lib/python3.10/site-packages/selenium/webdriver/chromium/webdriver.py", line 50, in __init__
    self.service.start()
  File "/usr/local/lib/python3.10/site-packages/selenium/webdriver/common/service.py", line 102, in start
    self.assert_process_still_running()
  File "/usr/local/lib/python3.10/site-packages/selenium/webdriver/common/service.py", line 115, in assert_process_still_running
    raise WebDriverException(f"Service {self._path} unexpectedly exited. Status code was: {return_code}")
selenium.common.exceptions.WebDriverException: Message: Service /root/.cache/selenium/msedgedriver/linux64/123.0.2420.53/msedgedriver unexpectedly exited. Status code was: 127

[2024-03-26 06:38:39,926: WARNING/MainProcess] /usr/local/lib/python3.10/site-packages/celery/worker/consumer/consumer.py:507: CPendingDeprecationWarning: The broker_connection_retry configuration setting will no longer determine
whether broker connection retries are made during startup in Celery 6.0 and above.
If you wish to retain the existing behavior for retrying connections on startup,
you should set broker_connection_retry_on_startup to True.
  warnings.warn(

[2024-03-26 06:38:39,943: INFO/MainProcess] Connected to redis://redis:6379/0
[2024-03-26 06:38:39,944: WARNING/MainProcess] /usr/local/lib/python3.10/site-packages/celery/worker/consumer/consumer.py:507: CPendingDeprecationWarning: The broker_connection_retry configuration setting will no longer determine
whether broker connection retries are made during startup in Celery 6.0 and above.
If you wish to retain the existing behavior for retrying connections on startup,
you should set broker_connection_retry_on_startup to True.
  warnings.warn(

[2024-03-26 06:38:39,948: INFO/MainProcess] mingle: searching for neighbors
[2024-03-26 06:38:40,962: INFO/MainProcess] mingle: all alone
[2024-03-26 06:38:40,985: INFO/MainProcess] celery@6f3d5a9bcbb4 ready.
[2024-03-26 06:38:40,990: INFO/MainProcess] Task tracker.tasks.cel_scraper[60093494-b5e6-46b5-82fb-d91a637ae586] received
[2024-03-26 06:40:00,027: ERROR/MainProcess] Task tracker.tasks.cel_scraper[60093494-b5e6-46b5-82fb-d91a637ae586] raised unexpected: WebDriverException()
Traceback (most recent call last):
  File "/usr/local/lib/python3.10/site-packages/celery/app/trace.py", line 477, in trace_task
    R = retval = fun(*args, **kwargs)
  File "/usr/local/lib/python3.10/site-packages/celery/app/trace.py", line 760, in __protected_call__
    return self.run(*args, **kwargs)
  File "/usr/src/app/tracker/tasks.py", line 14, in cel_scraper
    scraper.scrape()
  File "/usr/src/app/tracker/Utils/Scraper.py", line 26, in scrape
    data = self.scrape_data(url)
  File "/usr/src/app/tracker/Utils/Scraper.py", line 58, in scrape_data
    browser = webdriver.Edge(options=options)
  File "/usr/local/lib/python3.10/site-packages/selenium/webdriver/edge/webdriver.py", line 45, in __init__
    super().__init__(
  File "/usr/local/lib/python3.10/site-packages/selenium/webdriver/chromium/webdriver.py", line 50, in __init__
    self.service.start()
  File "/usr/local/lib/python3.10/site-packages/selenium/webdriver/common/service.py", line 102, in start
    self.assert_process_still_running()
  File "/usr/local/lib/python3.10/site-packages/selenium/webdriver/common/service.py", line 115, in assert_process_still_running
    raise WebDriverException(f"Service {self._path} unexpectedly exited. Status code was: {return_code}")
selenium.common.exceptions.WebDriverException: Message: Service /root/.cache/selenium/msedgedriver/linux64/123.0.2420.53/msedgedriver unexpectedly exited. Status code was: 127

[2024-03-26 06:40:00,310: INFO/MainProcess] Task tracker.tasks.cel_scraper[c9ae1c5f-e458-400f-ab7c-152123ac189e] received
[2024-03-26 06:40:00,614: ERROR/MainProcess] Task tracker.tasks.cel_scraper[c9ae1c5f-e458-400f-ab7c-152123ac189e] raised unexpected: WebDriverException()
Traceback (most recent call last):
  File "/usr/local/lib/python3.10/site-packages/celery/app/trace.py", line 477, in trace_task
    R = retval = fun(*args, **kwargs)
  File "/usr/local/lib/python3.10/site-packages/celery/app/trace.py", line 760, in __protected_call__
    return self.run(*args, **kwargs)
  File "/usr/src/app/tracker/tasks.py", line 14, in cel_scraper
    scraper.scrape()
  File "/usr/src/app/tracker/Utils/Scraper.py", line 26, in scrape
    data = self.scrape_data(url)
  File "/usr/src/app/tracker/Utils/Scraper.py", line 58, in scrape_data
    browser = webdriver.Edge(options=options)
  File "/usr/local/lib/python3.10/site-packages/selenium/webdriver/edge/webdriver.py", line 45, in __init__
    super().__init__(
  File "/usr/local/lib/python3.10/site-packages/selenium/webdriver/chromium/webdriver.py", line 50, in __init__
    self.service.start()
  File "/usr/local/lib/python3.10/site-packages/selenium/webdriver/common/service.py", line 102, in start
    self.assert_process_still_running()
  File "/usr/local/lib/python3.10/site-packages/selenium/webdriver/common/service.py", line 115, in assert_process_still_running
    raise WebDriverException(f"Service {self._path} unexpectedly exited. Status code was: {return_code}")
selenium.common.exceptions.WebDriverException: Message: Service /root/.cache/selenium/msedgedriver/linux64/123.0.2420.53/msedgedriver unexpectedly exited. Status code was: 127

[2024-03-26 06:40:00,631: INFO/MainProcess] Events of group {task} enabled by remote.
[2024-03-26 06:40:00,646: INFO/MainProcess] Task tracker.tasks.cel_scraper[5c9b11c0-4de4-4694-b995-11a0b7d2e956] received
[2024-03-26 06:40:00,745: ERROR/MainProcess] Task tracker.tasks.cel_scraper[5c9b11c0-4de4-4694-b995-11a0b7d2e956] raised unexpected: WebDriverException()
Traceback (most recent call last):
  File "/usr/local/lib/python3.10/site-packages/celery/app/trace.py", line 477, in trace_task
    R = retval = fun(*args, **kwargs)
  File "/usr/local/lib/python3.10/site-packages/celery/app/trace.py", line 760, in __protected_call__
    return self.run(*args, **kwargs)
  File "/usr/src/app/tracker/tasks.py", line 14, in cel_scraper
    scraper.scrape()
  File "/usr/src/app/tracker/Utils/Scraper.py", line 26, in scrape
    data = self.scrape_data(url)
  File "/usr/src/app/tracker/Utils/Scraper.py", line 58, in scrape_data
    browser = webdriver.Edge(options=options)
  File "/usr/local/lib/python3.10/site-packages/selenium/webdriver/edge/webdriver.py", line 45, in __init__
    super().__init__(
  File "/usr/local/lib/python3.10/site-packages/selenium/webdriver/chromium/webdriver.py", line 50, in __init__
    self.service.start()
  File "/usr/local/lib/python3.10/site-packages/selenium/webdriver/common/service.py", line 102, in start
    self.assert_process_still_running()
  File "/usr/local/lib/python3.10/site-packages/selenium/webdriver/common/service.py", line 115, in assert_process_still_running
    raise WebDriverException(f"Service {self._path} unexpectedly exited. Status code was: {return_code}")
selenium.common.exceptions.WebDriverException: Message: Service /root/.cache/selenium/msedgedriver/linux64/123.0.2420.53/msedgedriver unexpectedly exited. Status code was: 127

[2024-03-26 06:44:18,676: WARNING/MainProcess] /usr/local/lib/python3.10/site-packages/celery/worker/consumer/consumer.py:507: CPendingDeprecationWarning: The broker_connection_retry configuration setting will no longer determine
whether broker connection retries are made during startup in Celery 6.0 and above.
If you wish to retain the existing behavior for retrying connections on startup,
you should set broker_connection_retry_on_startup to True.
  warnings.warn(

[2024-03-26 06:44:18,731: INFO/MainProcess] Connected to redis://redis:6379/0
[2024-03-26 06:44:18,733: WARNING/MainProcess] /usr/local/lib/python3.10/site-packages/celery/worker/consumer/consumer.py:507: CPendingDeprecationWarning: The broker_connection_retry configuration setting will no longer determine
whether broker connection retries are made during startup in Celery 6.0 and above.
If you wish to retain the existing behavior for retrying connections on startup,
you should set broker_connection_retry_on_startup to True.
  warnings.warn(

[2024-03-26 06:44:18,741: INFO/MainProcess] mingle: searching for neighbors
[2024-03-26 06:44:19,780: INFO/MainProcess] mingle: all alone
[2024-03-26 06:44:19,807: INFO/MainProcess] celery@0173f18a54c4 ready.
[2024-03-26 06:44:19,814: INFO/MainProcess] Task tracker.tasks.cel_scraper[7abb5443-de5a-44ff-bc40-2230629156a3] received
[2024-03-26 06:45:37,997: ERROR/MainProcess] Task tracker.tasks.cel_scraper[7abb5443-de5a-44ff-bc40-2230629156a3] raised unexpected: WebDriverException()
Traceback (most recent call last):
  File "/usr/local/lib/python3.10/site-packages/celery/app/trace.py", line 477, in trace_task
    R = retval = fun(*args, **kwargs)
  File "/usr/local/lib/python3.10/site-packages/celery/app/trace.py", line 760, in __protected_call__
    return self.run(*args, **kwargs)
  File "/usr/src/app/tracker/tasks.py", line 14, in cel_scraper
    scraper.scrape()
  File "/usr/src/app/tracker/Utils/Scraper.py", line 26, in scrape
    data = self.scrape_data(url)
  File "/usr/src/app/tracker/Utils/Scraper.py", line 58, in scrape_data
    browser = webdriver.Edge(options=options)
  File "/usr/local/lib/python3.10/site-packages/selenium/webdriver/edge/webdriver.py", line 45, in __init__
    super().__init__(
  File "/usr/local/lib/python3.10/site-packages/selenium/webdriver/chromium/webdriver.py", line 50, in __init__
    self.service.start()
  File "/usr/local/lib/python3.10/site-packages/selenium/webdriver/common/service.py", line 102, in start
    self.assert_process_still_running()
  File "/usr/local/lib/python3.10/site-packages/selenium/webdriver/common/service.py", line 115, in assert_process_still_running
    raise WebDriverException(f"Service {self._path} unexpectedly exited. Status code was: {return_code}")
selenium.common.exceptions.WebDriverException: Message: Service /root/.cache/selenium/msedgedriver/linux64/123.0.2420.53/msedgedriver unexpectedly exited. Status code was: 127

[2024-03-26 06:45:38,835: INFO/MainProcess] Task tracker.tasks.cel_scraper[b1cffce6-1a2d-47f2-9e84-b1a6a08c0dd9] received
[2024-03-26 06:45:40,085: ERROR/MainProcess] Task tracker.tasks.cel_scraper[b1cffce6-1a2d-47f2-9e84-b1a6a08c0dd9] raised unexpected: WebDriverException()
Traceback (most recent call last):
  File "/usr/local/lib/python3.10/site-packages/celery/app/trace.py", line 477, in trace_task
    R = retval = fun(*args, **kwargs)
  File "/usr/local/lib/python3.10/site-packages/celery/app/trace.py", line 760, in __protected_call__
    return self.run(*args, **kwargs)
  File "/usr/src/app/tracker/tasks.py", line 14, in cel_scraper
    scraper.scrape()
  File "/usr/src/app/tracker/Utils/Scraper.py", line 26, in scrape
    data = self.scrape_data(url)
  File "/usr/src/app/tracker/Utils/Scraper.py", line 58, in scrape_data
    browser = webdriver.Edge(options=options)
  File "/usr/local/lib/python3.10/site-packages/selenium/webdriver/edge/webdriver.py", line 45, in __init__
    super().__init__(
  File "/usr/local/lib/python3.10/site-packages/selenium/webdriver/chromium/webdriver.py", line 50, in __init__
    self.service.start()
  File "/usr/local/lib/python3.10/site-packages/selenium/webdriver/common/service.py", line 102, in start
    self.assert_process_still_running()
  File "/usr/local/lib/python3.10/site-packages/selenium/webdriver/common/service.py", line 115, in assert_process_still_running
    raise WebDriverException(f"Service {self._path} unexpectedly exited. Status code was: {return_code}")
selenium.common.exceptions.WebDriverException: Message: Service /root/.cache/selenium/msedgedriver/linux64/123.0.2420.53/msedgedriver unexpectedly exited. Status code was: 127

[2024-03-26 06:46:01,145: INFO/MainProcess] Task tracker.tasks.cel_scraper[8064826c-0917-4d8d-a4a0-c99dfd7d38c5] received
[2024-03-26 06:46:01,854: ERROR/MainProcess] Task tracker.tasks.cel_scraper[8064826c-0917-4d8d-a4a0-c99dfd7d38c5] raised unexpected: WebDriverException()
Traceback (most recent call last):
  File "/usr/local/lib/python3.10/site-packages/celery/app/trace.py", line 477, in trace_task
    R = retval = fun(*args, **kwargs)
  File "/usr/local/lib/python3.10/site-packages/celery/app/trace.py", line 760, in __protected_call__
    return self.run(*args, **kwargs)
  File "/usr/src/app/tracker/tasks.py", line 14, in cel_scraper
    scraper.scrape()
  File "/usr/src/app/tracker/Utils/Scraper.py", line 26, in scrape
    data = self.scrape_data(url)
  File "/usr/src/app/tracker/Utils/Scraper.py", line 58, in scrape_data
    browser = webdriver.Edge(options=options)
  File "/usr/local/lib/python3.10/site-packages/selenium/webdriver/edge/webdriver.py", line 45, in __init__
    super().__init__(
  File "/usr/local/lib/python3.10/site-packages/selenium/webdriver/chromium/webdriver.py", line 50, in __init__
    self.service.start()
  File "/usr/local/lib/python3.10/site-packages/selenium/webdriver/common/service.py", line 102, in start
    self.assert_process_still_running()
  File "/usr/local/lib/python3.10/site-packages/selenium/webdriver/common/service.py", line 115, in assert_process_still_running
    raise WebDriverException(f"Service {self._path} unexpectedly exited. Status code was: {return_code}")
selenium.common.exceptions.WebDriverException: Message: Service /root/.cache/selenium/msedgedriver/linux64/123.0.2420.53/msedgedriver unexpectedly exited. Status code was: 127

[2024-03-26 06:47:00,371: INFO/MainProcess] Task tracker.tasks.cel_scraper[a4441b4f-c1ec-4556-9c0c-9b43fd96938e] received
[2024-03-26 06:47:03,800: ERROR/MainProcess] Task tracker.tasks.cel_scraper[a4441b4f-c1ec-4556-9c0c-9b43fd96938e] raised unexpected: WebDriverException()
Traceback (most recent call last):
  File "/usr/local/lib/python3.10/site-packages/celery/app/trace.py", line 477, in trace_task
    R = retval = fun(*args, **kwargs)
  File "/usr/local/lib/python3.10/site-packages/celery/app/trace.py", line 760, in __protected_call__
    return self.run(*args, **kwargs)
  File "/usr/src/app/tracker/tasks.py", line 14, in cel_scraper
    scraper.scrape()
  File "/usr/src/app/tracker/Utils/Scraper.py", line 26, in scrape
    data = self.scrape_data(url)
  File "/usr/src/app/tracker/Utils/Scraper.py", line 58, in scrape_data
    browser = webdriver.Edge(options=options)
  File "/usr/local/lib/python3.10/site-packages/selenium/webdriver/edge/webdriver.py", line 45, in __init__
    super().__init__(
  File "/usr/local/lib/python3.10/site-packages/selenium/webdriver/chromium/webdriver.py", line 50, in __init__
    self.service.start()
  File "/usr/local/lib/python3.10/site-packages/selenium/webdriver/common/service.py", line 102, in start
    self.assert_process_still_running()
  File "/usr/local/lib/python3.10/site-packages/selenium/webdriver/common/service.py", line 115, in assert_process_still_running
    raise WebDriverException(f"Service {self._path} unexpectedly exited. Status code was: {return_code}")
selenium.common.exceptions.WebDriverException: Message: Service /root/.cache/selenium/msedgedriver/linux64/123.0.2420.53/msedgedriver unexpectedly exited. Status code was: 127

[2024-03-26 06:48:00,905: INFO/MainProcess] Task tracker.tasks.cel_scraper[3769fea5-8f1a-4e79-af5d-77ed78b2e43c] received
[2024-03-26 06:48:02,560: ERROR/MainProcess] Task tracker.tasks.cel_scraper[3769fea5-8f1a-4e79-af5d-77ed78b2e43c] raised unexpected: WebDriverException()
Traceback (most recent call last):
  File "/usr/local/lib/python3.10/site-packages/celery/app/trace.py", line 477, in trace_task
    R = retval = fun(*args, **kwargs)
  File "/usr/local/lib/python3.10/site-packages/celery/app/trace.py", line 760, in __protected_call__
    return self.run(*args, **kwargs)
  File "/usr/src/app/tracker/tasks.py", line 14, in cel_scraper
    scraper.scrape()
  File "/usr/src/app/tracker/Utils/Scraper.py", line 26, in scrape
    data = self.scrape_data(url)
  File "/usr/src/app/tracker/Utils/Scraper.py", line 58, in scrape_data
    browser = webdriver.Edge(options=options)
  File "/usr/local/lib/python3.10/site-packages/selenium/webdriver/edge/webdriver.py", line 45, in __init__
    super().__init__(
  File "/usr/local/lib/python3.10/site-packages/selenium/webdriver/chromium/webdriver.py", line 50, in __init__
    self.service.start()
  File "/usr/local/lib/python3.10/site-packages/selenium/webdriver/common/service.py", line 102, in start
    self.assert_process_still_running()
  File "/usr/local/lib/python3.10/site-packages/selenium/webdriver/common/service.py", line 115, in assert_process_still_running
    raise WebDriverException(f"Service {self._path} unexpectedly exited. Status code was: {return_code}")
selenium.common.exceptions.WebDriverException: Message: Service /root/.cache/selenium/msedgedriver/linux64/123.0.2420.53/msedgedriver unexpectedly exited. Status code was: 127

[2024-03-26 06:50:44,599: WARNING/MainProcess] /usr/local/lib/python3.10/site-packages/celery/worker/consumer/consumer.py:507: CPendingDeprecationWarning: The broker_connection_retry configuration setting will no longer determine
whether broker connection retries are made during startup in Celery 6.0 and above.
If you wish to retain the existing behavior for retrying connections on startup,
you should set broker_connection_retry_on_startup to True.
  warnings.warn(

[2024-03-26 06:50:44,666: INFO/MainProcess] Connected to redis://redis:6379/0
[2024-03-26 06:50:44,670: WARNING/MainProcess] /usr/local/lib/python3.10/site-packages/celery/worker/consumer/consumer.py:507: CPendingDeprecationWarning: The broker_connection_retry configuration setting will no longer determine
whether broker connection retries are made during startup in Celery 6.0 and above.
If you wish to retain the existing behavior for retrying connections on startup,
you should set broker_connection_retry_on_startup to True.
  warnings.warn(

[2024-03-26 06:50:44,677: INFO/MainProcess] mingle: searching for neighbors
[2024-03-26 06:50:45,767: INFO/MainProcess] mingle: all alone
[2024-03-26 06:50:46,028: INFO/MainProcess] celery@b576f7a2b709 ready.
[2024-03-26 06:50:46,216: INFO/MainProcess] Task tracker.tasks.cel_scraper[44fc02dc-4ce2-45c3-ac0d-ef5dfb6cf8b7] received
[2024-03-26 06:52:14,840: WARNING/MainProcess] /usr/local/lib/python3.10/site-packages/celery/worker/consumer/consumer.py:507: CPendingDeprecationWarning: The broker_connection_retry configuration setting will no longer determine
whether broker connection retries are made during startup in Celery 6.0 and above.
If you wish to retain the existing behavior for retrying connections on startup,
you should set broker_connection_retry_on_startup to True.
  warnings.warn(

[2024-03-26 06:52:14,882: INFO/MainProcess] Connected to redis://redis:6379/0
[2024-03-26 06:52:14,885: WARNING/MainProcess] /usr/local/lib/python3.10/site-packages/celery/worker/consumer/consumer.py:507: CPendingDeprecationWarning: The broker_connection_retry configuration setting will no longer determine
whether broker connection retries are made during startup in Celery 6.0 and above.
If you wish to retain the existing behavior for retrying connections on startup,
you should set broker_connection_retry_on_startup to True.
  warnings.warn(

[2024-03-26 06:52:14,892: INFO/MainProcess] mingle: searching for neighbors
[2024-03-26 06:52:15,929: INFO/MainProcess] mingle: all alone
[2024-03-26 06:52:16,031: INFO/MainProcess] celery@1139921469aa ready.
[2024-03-26 06:52:16,050: INFO/MainProcess] Task tracker.tasks.cel_scraper[1275526f-e5c6-4447-9b05-725b23976573] received
[2024-03-26 06:55:52,539: WARNING/MainProcess] /usr/local/lib/python3.10/site-packages/celery/worker/consumer/consumer.py:507: CPendingDeprecationWarning: The broker_connection_retry configuration setting will no longer determine
whether broker connection retries are made during startup in Celery 6.0 and above.
If you wish to retain the existing behavior for retrying connections on startup,
you should set broker_connection_retry_on_startup to True.
  warnings.warn(

[2024-03-26 06:55:52,669: INFO/MainProcess] Connected to redis://redis:6379/0
[2024-03-26 06:55:52,683: WARNING/MainProcess] /usr/local/lib/python3.10/site-packages/celery/worker/consumer/consumer.py:507: CPendingDeprecationWarning: The broker_connection_retry configuration setting will no longer determine
whether broker connection retries are made during startup in Celery 6.0 and above.
If you wish to retain the existing behavior for retrying connections on startup,
you should set broker_connection_retry_on_startup to True.
  warnings.warn(

[2024-03-26 06:55:52,717: INFO/MainProcess] mingle: searching for neighbors
[2024-03-26 06:55:53,849: INFO/MainProcess] mingle: all alone
[2024-03-26 06:55:54,404: INFO/MainProcess] celery@472e45d17d7c ready.
[2024-03-26 06:55:54,692: INFO/MainProcess] Task tracker.tasks.cel_scraper[9db0bb6a-f0fe-4cb2-9c48-1a0711a947ac] received
